Django Server Started
[nltk_data] Downloading package punkt to /root/nltk_data...
[nltk_data]   Package punkt is already up-to-date!
[nltk_data] Downloading package averaged_perceptron_tagger to
[nltk_data]     /root/nltk_data...
[nltk_data]   Package averaged_perceptron_tagger is already up-to-
[nltk_data]       date!
[nltk_data] Downloading package wordnet to /root/nltk_data...
[nltk_data]   Package wordnet is already up-to-date!
Geted data from database
do_insert_page_info insert failed: 1062 (23000): Duplicate entry '4780-polomono' for key 'PRIMARY'
Finding web-page failed:  Alert Text: 잘못된 접근 경로입니다. 다시 시도해 주세요.
Message: unexpected alert open: {Alert text : 잘못된 접근 경로입니다. 다시 시도해 주세요.}
  (Session info: chrome-headless-shell=126.0.6478.126)
Stacktrace:
#0 0x55e556ef1cba <unknown>
#1 0x55e556bd4e2c <unknown>
#2 0x55e556c63d63 <unknown>
#3 0x55e556c44363 <unknown>
#4 0x55e556c14247 <unknown>
#5 0x55e556c14b9e <unknown>
#6 0x55e556eb828b <unknown>
#7 0x55e556ebc331 <unknown>
#8 0x55e556ea3b3e <unknown>
#9 0x55e556ebce92 <unknown>
#10 0x55e556e887df <unknown>
#11 0x55e556ee1678 <unknown>
#12 0x55e556ee1850 <unknown>
#13 0x55e556ef0dec <unknown>
#14 0x7fada73e2ac3 <unknown>

Finding web-page failed:  Alert Text: 잘못된 접근 경로입니다. 다시 시도해 주세요.
Message: unexpected alert open: {Alert text : 잘못된 접근 경로입니다. 다시 시도해 주세요.}
  (Session info: chrome-headless-shell=126.0.6478.126)
Stacktrace:
#0 0x557f76b88cba <unknown>
#1 0x557f7686be2c <unknown>
#2 0x557f768fad63 <unknown>
#3 0x557f768db363 <unknown>
#4 0x557f768ab247 <unknown>
#5 0x557f768abb9e <unknown>
#6 0x557f76b4f28b <unknown>
#7 0x557f76b53331 <unknown>
#8 0x557f76b3ab3e <unknown>
#9 0x557f76b53e92 <unknown>
#10 0x557f76b1f7df <unknown>
#11 0x557f76b78678 <unknown>
#12 0x557f76b78850 <unknown>
#13 0x557f76b87dec <unknown>
#14 0x7fd1b0b4dac3 <unknown>

meaning of bizarre is completed(2)
Internal Server Error: /article/confirm-wordcheck/
Traceback (most recent call last):
  File "/root/pyDjangoDEV/mdmproj1/.venv/lib/python3.10/site-packages/django/core/handlers/exception.py", line 55, in inner
    response = get_response(request)
  File "/root/pyDjangoDEV/mdmproj1/.venv/lib/python3.10/site-packages/django/core/handlers/base.py", line 197, in _get_response
    response = wrapped_callback(request, *callback_args, **callback_kwargs)
  File "/root/pyDjangoDEV/mdmproj1/.venv/lib/python3.10/site-packages/django/views/decorators/csrf.py", line 56, in wrapper_view
    return view_func(*args, **kwargs)
  File "/root/pyDjangoDEV/mdmproj1/.venv/lib/python3.10/site-packages/django/contrib/auth/decorators.py", line 23, in _wrapper_view
    return view_func(request, *args, **kwargs)
  File "/root/pyDjangoDEV/mdmproj1/article/views.py", line 788, in confirm_word_check
    close_connection(conn, cursor)
  File "/root/pyDjangoDEV/mdmproj1/mdl_sql_mapping/__init__.py", line 19, in close_connection
    conn.commit()
  File "/root/pyDjangoDEV/mdmproj1/.venv/lib/python3.10/site-packages/mysql/connector/connection_cext.py", line 517, in commit
    self._cmysql.commit()
_mysql_connector.MySQLInterfaceError: MySQL server has gone away
Internal Server Error: /article/create-word/
Traceback (most recent call last):
  File "/root/pyDjangoDEV/mdmproj1/.venv/lib/python3.10/site-packages/django/core/handlers/exception.py", line 55, in inner
    response = get_response(request)
  File "/root/pyDjangoDEV/mdmproj1/.venv/lib/python3.10/site-packages/django/core/handlers/base.py", line 204, in _get_response
    self.check_response(response, callback)
  File "/root/pyDjangoDEV/mdmproj1/.venv/lib/python3.10/site-packages/django/core/handlers/base.py", line 332, in check_response
    raise ValueError(
ValueError: The view article.views.create_word didn't return an HttpResponse object. It returned None instead.
meaning of bizarre is completed(1)
meaning of irk is completed(2)
Internal Server Error: /article/confirm-wordcheck/
Traceback (most recent call last):
  File "/root/pyDjangoDEV/mdmproj1/.venv/lib/python3.10/site-packages/django/core/handlers/exception.py", line 55, in inner
    response = get_response(request)
  File "/root/pyDjangoDEV/mdmproj1/.venv/lib/python3.10/site-packages/django/core/handlers/base.py", line 197, in _get_response
    response = wrapped_callback(request, *callback_args, **callback_kwargs)
  File "/root/pyDjangoDEV/mdmproj1/.venv/lib/python3.10/site-packages/django/views/decorators/csrf.py", line 56, in wrapper_view
    return view_func(*args, **kwargs)
  File "/root/pyDjangoDEV/mdmproj1/.venv/lib/python3.10/site-packages/django/contrib/auth/decorators.py", line 23, in _wrapper_view
    return view_func(request, *args, **kwargs)
  File "/root/pyDjangoDEV/mdmproj1/article/views.py", line 788, in confirm_word_check
    close_connection(conn, cursor)
  File "/root/pyDjangoDEV/mdmproj1/mdl_sql_mapping/__init__.py", line 19, in close_connection
    conn.commit()
  File "/root/pyDjangoDEV/mdmproj1/.venv/lib/python3.10/site-packages/mysql/connector/connection_cext.py", line 517, in commit
    self._cmysql.commit()
_mysql_connector.MySQLInterfaceError: MySQL server has gone away
meaning of cordially is completed(1)
meaning of inauguration is completed(1)
meaning of isle is completed(1)
meaning of operatic is completed(2)
meaning of rajjles is completed(1)
Internal Server Error: /article/confirm-wordcheck/
Traceback (most recent call last):
  File "/root/pyDjangoDEV/mdmproj1/.venv/lib/python3.10/site-packages/django/core/handlers/exception.py", line 55, in inner
    response = get_response(request)
  File "/root/pyDjangoDEV/mdmproj1/.venv/lib/python3.10/site-packages/django/core/handlers/base.py", line 197, in _get_response
    response = wrapped_callback(request, *callback_args, **callback_kwargs)
  File "/root/pyDjangoDEV/mdmproj1/.venv/lib/python3.10/site-packages/django/views/decorators/csrf.py", line 56, in wrapper_view
    return view_func(*args, **kwargs)
  File "/root/pyDjangoDEV/mdmproj1/.venv/lib/python3.10/site-packages/django/contrib/auth/decorators.py", line 23, in _wrapper_view
    return view_func(request, *args, **kwargs)
  File "/root/pyDjangoDEV/mdmproj1/article/views.py", line 788, in confirm_word_check
    close_connection(conn, cursor)
  File "/root/pyDjangoDEV/mdmproj1/mdl_sql_mapping/__init__.py", line 19, in close_connection
    conn.commit()
  File "/root/pyDjangoDEV/mdmproj1/.venv/lib/python3.10/site-packages/mysql/connector/connection_cext.py", line 517, in commit
    self._cmysql.commit()
_mysql_connector.MySQLInterfaceError: MySQL server has gone away
do_insert_page_info insert failed: 1062 (23000): Duplicate entry '4781-polomono' for key 'PRIMARY'
Finding web-page failed:  Alert Text: 잘못된 접근 경로입니다. 다시 시도해 주세요.
Message: unexpected alert open: {Alert text : 잘못된 접근 경로입니다. 다시 시도해 주세요.}
  (Session info: chrome-headless-shell=126.0.6478.126)
Stacktrace:
#0 0x561f5d495cba <unknown>
#1 0x561f5d178e2c <unknown>
#2 0x561f5d207d63 <unknown>
#3 0x561f5d1e8363 <unknown>
#4 0x561f5d1b8247 <unknown>
#5 0x561f5d1b8b9e <unknown>
#6 0x561f5d45c28b <unknown>
#7 0x561f5d460331 <unknown>
#8 0x561f5d447b3e <unknown>
#9 0x561f5d460e92 <unknown>
#10 0x561f5d42c7df <unknown>
#11 0x561f5d485678 <unknown>
#12 0x561f5d485850 <unknown>
#13 0x561f5d494dec <unknown>
#14 0x7fea6574dac3 <unknown>

Finding web-page failed:  Alert Text: 잘못된 접근 경로입니다. 다시 시도해 주세요.
Message: unexpected alert open: {Alert text : 잘못된 접근 경로입니다. 다시 시도해 주세요.}
  (Session info: chrome-headless-shell=126.0.6478.126)
Stacktrace:
#0 0x55a3fcc69cba <unknown>
#1 0x55a3fc94ce2c <unknown>
#2 0x55a3fc9dbd63 <unknown>
#3 0x55a3fc9bc363 <unknown>
#4 0x55a3fc98c247 <unknown>
#5 0x55a3fc98cb9e <unknown>
#6 0x55a3fcc3028b <unknown>
#7 0x55a3fcc34331 <unknown>
#8 0x55a3fcc1bb3e <unknown>
#9 0x55a3fcc34e92 <unknown>
#10 0x55a3fcc007df <unknown>
#11 0x55a3fcc59678 <unknown>
#12 0x55a3fcc59850 <unknown>
#13 0x55a3fcc68dec <unknown>
#14 0x7f6a3269fac3 <unknown>

Geted data from database
Geted data from database
Geted data from database
do_insert_page_info insert failed: 1062 (23000): Duplicate entry '4782-polomono' for key 'PRIMARY'
Finding web-page failed:  Alert Text: 잘못된 접근 경로입니다. 다시 시도해 주세요.
Message: unexpected alert open: {Alert text : 잘못된 접근 경로입니다. 다시 시도해 주세요.}
  (Session info: chrome-headless-shell=126.0.6478.126)
Stacktrace:
#0 0x55f7ff449cba <unknown>
#1 0x55f7ff12ce2c <unknown>
#2 0x55f7ff1bbd63 <unknown>
#3 0x55f7ff19c363 <unknown>
#4 0x55f7ff16c247 <unknown>
#5 0x55f7ff16cb9e <unknown>
#6 0x55f7ff41028b <unknown>
#7 0x55f7ff414331 <unknown>
#8 0x55f7ff3fbb3e <unknown>
#9 0x55f7ff414e92 <unknown>
#10 0x55f7ff3e07df <unknown>
#11 0x55f7ff439678 <unknown>
#12 0x55f7ff439850 <unknown>
#13 0x55f7ff448dec <unknown>
#14 0x7f2cb002dac3 <unknown>

Finding web-page failed:  Alert Text: 잘못된 접근 경로입니다. 다시 시도해 주세요.
Message: unexpected alert open: {Alert text : 잘못된 접근 경로입니다. 다시 시도해 주세요.}
  (Session info: chrome-headless-shell=126.0.6478.126)
Stacktrace:
#0 0x562e0f9e8cba <unknown>
#1 0x562e0f6cbe2c <unknown>
#2 0x562e0f75ad63 <unknown>
#3 0x562e0f73b363 <unknown>
#4 0x562e0f70b247 <unknown>
#5 0x562e0f70bb9e <unknown>
#6 0x562e0f9af28b <unknown>
#7 0x562e0f9b3331 <unknown>
#8 0x562e0f99ab3e <unknown>
#9 0x562e0f9b3e92 <unknown>
#10 0x562e0f97f7df <unknown>
#11 0x562e0f9d8678 <unknown>
#12 0x562e0f9d8850 <unknown>
#13 0x562e0f9e7dec <unknown>
#14 0x7fcb1fca9ac3 <unknown>

meaning of booster is completed(2)
meaning of finer is completed(2)
meaning of hygiene is completed(1)
Internal Server Error: /article/confirm-wordcheck/
Traceback (most recent call last):
  File "/root/pyDjangoDEV/mdmproj1/.venv/lib/python3.10/site-packages/django/core/handlers/exception.py", line 55, in inner
    response = get_response(request)
  File "/root/pyDjangoDEV/mdmproj1/.venv/lib/python3.10/site-packages/django/core/handlers/base.py", line 197, in _get_response
    response = wrapped_callback(request, *callback_args, **callback_kwargs)
  File "/root/pyDjangoDEV/mdmproj1/.venv/lib/python3.10/site-packages/django/views/decorators/csrf.py", line 56, in wrapper_view
    return view_func(*args, **kwargs)
  File "/root/pyDjangoDEV/mdmproj1/.venv/lib/python3.10/site-packages/django/contrib/auth/decorators.py", line 23, in _wrapper_view
    return view_func(request, *args, **kwargs)
  File "/root/pyDjangoDEV/mdmproj1/article/views.py", line 788, in confirm_word_check
    close_connection(conn, cursor)
  File "/root/pyDjangoDEV/mdmproj1/mdl_sql_mapping/__init__.py", line 19, in close_connection
    conn.commit()
  File "/root/pyDjangoDEV/mdmproj1/.venv/lib/python3.10/site-packages/mysql/connector/connection_cext.py", line 517, in commit
    self._cmysql.commit()
_mysql_connector.MySQLInterfaceError: MySQL server has gone away
Django Server Started
[nltk_data] Downloading package punkt to /root/nltk_data...
[nltk_data]   Package punkt is already up-to-date!
[nltk_data] Downloading package averaged_perceptron_tagger to
[nltk_data]     /root/nltk_data...
[nltk_data]   Package averaged_perceptron_tagger is already up-to-
[nltk_data]       date!
[nltk_data] Downloading package wordnet to /root/nltk_data...
[nltk_data]   Package wordnet is already up-to-date!
do_insert_page_info insert failed: 1062 (23000): Duplicate entry '4782-polomono' for key 'PRIMARY'
Finding web-page failed:  Alert Text: 잘못된 접근 경로입니다. 다시 시도해 주세요.
Message: unexpected alert open: {Alert text : 잘못된 접근 경로입니다. 다시 시도해 주세요.}
  (Session info: chrome-headless-shell=126.0.6478.126)
Stacktrace:
#0 0x55c0afce9cba <unknown>
#1 0x55c0af9cce2c <unknown>
#2 0x55c0afa5bd63 <unknown>
#3 0x55c0afa3c363 <unknown>
#4 0x55c0afa0c247 <unknown>
#5 0x55c0afa0cb9e <unknown>
#6 0x55c0afcb028b <unknown>
#7 0x55c0afcb4331 <unknown>
#8 0x55c0afc9bb3e <unknown>
#9 0x55c0afcb4e92 <unknown>
#10 0x55c0afc807df <unknown>
#11 0x55c0afcd9678 <unknown>
#12 0x55c0afcd9850 <unknown>
#13 0x55c0afce8dec <unknown>
#14 0x7f89d48ebac3 <unknown>

Finding web-page failed:  Alert Text: 잘못된 접근 경로입니다. 다시 시도해 주세요.
Message: unexpected alert open: {Alert text : 잘못된 접근 경로입니다. 다시 시도해 주세요.}
  (Session info: chrome-headless-shell=126.0.6478.126)
Stacktrace:
#0 0x5631a6e58cba <unknown>
#1 0x5631a6b3be2c <unknown>
#2 0x5631a6bcad63 <unknown>
#3 0x5631a6bab363 <unknown>
#4 0x5631a6b7b247 <unknown>
#5 0x5631a6b7bb9e <unknown>
#6 0x5631a6e1f28b <unknown>
#7 0x5631a6e23331 <unknown>
#8 0x5631a6e0ab3e <unknown>
#9 0x5631a6e23e92 <unknown>
#10 0x5631a6def7df <unknown>
#11 0x5631a6e48678 <unknown>
#12 0x5631a6e48850 <unknown>
#13 0x5631a6e57dec <unknown>
#14 0x7f83098c6ac3 <unknown>

Call Process Count failed: 'NoneType' object is not subscriptable
Call Process Count failed: 'NoneType' object is not subscriptable
Call Process Count failed: 'NoneType' object is not subscriptable
meaning of colic is completed(2)
meaning of confidante is completed(2)
meaning of contender is completed(2)
meaning of delmonte is completed(2)
meaning of equestrian is completed(2)
meaning of hagman is completed(2)
meaning of schaudt is completed(2)
meaning of strap is completed(2)
Geted data from database
Geted data from database
do_insert_page_info insert failed: 1062 (23000): Duplicate entry '4782-polomono' for key 'PRIMARY'
Finding web-page failed:  Alert Text: 잘못된 접근 경로입니다. 다시 시도해 주세요.
Message: unexpected alert open: {Alert text : 잘못된 접근 경로입니다. 다시 시도해 주세요.}
  (Session info: chrome-headless-shell=126.0.6478.126)
Stacktrace:
#0 0x563cf0150cba <unknown>
#1 0x563cefe33e2c <unknown>
#2 0x563cefec2d63 <unknown>
#3 0x563cefea3363 <unknown>
#4 0x563cefe73247 <unknown>
#5 0x563cefe73b9e <unknown>
#6 0x563cf011728b <unknown>
#7 0x563cf011b331 <unknown>
#8 0x563cf0102b3e <unknown>
#9 0x563cf011be92 <unknown>
#10 0x563cf00e77df <unknown>
#11 0x563cf0140678 <unknown>
#12 0x563cf0140850 <unknown>
#13 0x563cf014fdec <unknown>
#14 0x7f23beed8ac3 <unknown>

Finding web-page failed:  Alert Text: 잘못된 접근 경로입니다. 다시 시도해 주세요.
Message: unexpected alert open: {Alert text : 잘못된 접근 경로입니다. 다시 시도해 주세요.}
  (Session info: chrome-headless-shell=126.0.6478.126)
Stacktrace:
#0 0x56399f76ecba <unknown>
#1 0x56399f451e2c <unknown>
#2 0x56399f4e0d63 <unknown>
#3 0x56399f4c1363 <unknown>
#4 0x56399f491247 <unknown>
#5 0x56399f491b9e <unknown>
#6 0x56399f73528b <unknown>
#7 0x56399f739331 <unknown>
#8 0x56399f720b3e <unknown>
#9 0x56399f739e92 <unknown>
#10 0x56399f7057df <unknown>
#11 0x56399f75e678 <unknown>
#12 0x56399f75e850 <unknown>
#13 0x56399f76ddec <unknown>
#14 0x7f0776540ac3 <unknown>

meaning of composure is completed(1)
do_insert_page_info insert failed: 1062 (23000): Duplicate entry '4783-polomono' for key 'PRIMARY'
Finding web-page failed:  Alert Text: 잘못된 접근 경로입니다. 다시 시도해 주세요.
Message: unexpected alert open: {Alert text : 잘못된 접근 경로입니다. 다시 시도해 주세요.}
  (Session info: chrome-headless-shell=126.0.6478.126)
Stacktrace:
#0 0x555e6cb2bcba <unknown>
#1 0x555e6c80ee2c <unknown>
#2 0x555e6c89dd63 <unknown>
#3 0x555e6c87e363 <unknown>
#4 0x555e6c84e247 <unknown>
#5 0x555e6c84eb9e <unknown>
#6 0x555e6caf228b <unknown>
#7 0x555e6caf6331 <unknown>
#8 0x555e6caddb3e <unknown>
#9 0x555e6caf6e92 <unknown>
#10 0x555e6cac27df <unknown>
#11 0x555e6cb1b678 <unknown>
#12 0x555e6cb1b850 <unknown>
#13 0x555e6cb2adec <unknown>
#14 0x7f6cc8714ac3 <unknown>

Finding web-page failed:  Alert Text: 잘못된 접근 경로입니다. 다시 시도해 주세요.
Message: unexpected alert open: {Alert text : 잘못된 접근 경로입니다. 다시 시도해 주세요.}
  (Session info: chrome-headless-shell=126.0.6478.126)
Stacktrace:
#0 0x55d3e53c4cba <unknown>
#1 0x55d3e50a7e2c <unknown>
#2 0x55d3e5136d63 <unknown>
#3 0x55d3e5117363 <unknown>
#4 0x55d3e50e7247 <unknown>
#5 0x55d3e50e7b9e <unknown>
#6 0x55d3e538b28b <unknown>
#7 0x55d3e538f331 <unknown>
#8 0x55d3e5376b3e <unknown>
#9 0x55d3e538fe92 <unknown>
#10 0x55d3e535b7df <unknown>
#11 0x55d3e53b4678 <unknown>
#12 0x55d3e53b4850 <unknown>
#13 0x55d3e53c3dec <unknown>
#14 0x7f09428b3ac3 <unknown>

meaning of aren is completed(1)
meaning of fishery is completed(1)
meaning of grapple is completed(2)
meaning of livestock is completed(1)
meaning of loom is completed(2)
meaning of paradigm is completed(2)
meaning of plummet is completed(2)
meaning of predominantly is completed(2)
meaning of stark is completed(2)
Django Server Started
Server Error :  [Errno 98] Address already in use
Django Server Started
Django Server Started
[nltk_data] Downloading package punkt to /root/nltk_data...
[nltk_data]   Package punkt is already up-to-date!
[nltk_data] Downloading package averaged_perceptron_tagger to
[nltk_data]     /root/nltk_data...
[nltk_data]   Package averaged_perceptron_tagger is already up-to-
[nltk_data]       date!
[nltk_data] Downloading package wordnet to /root/nltk_data...
[nltk_data]   Package wordnet is already up-to-date!
do_insert_page_info insert failed: 1062 (23000): Duplicate entry '4784-polomono' for key 'PRIMARY'
Finding web-page failed:  Alert Text: 잘못된 접근 경로입니다. 다시 시도해 주세요.
Message: unexpected alert open: {Alert text : 잘못된 접근 경로입니다. 다시 시도해 주세요.}
  (Session info: chrome-headless-shell=126.0.6478.126)
Stacktrace:
#0 0x559d7fd2bcba <unknown>
#1 0x559d7fa0ee2c <unknown>
#2 0x559d7fa9dd63 <unknown>
#3 0x559d7fa7e363 <unknown>
#4 0x559d7fa4e247 <unknown>
#5 0x559d7fa4eb9e <unknown>
#6 0x559d7fcf228b <unknown>
#7 0x559d7fcf6331 <unknown>
#8 0x559d7fcddb3e <unknown>
#9 0x559d7fcf6e92 <unknown>
#10 0x559d7fcc27df <unknown>
#11 0x559d7fd1b678 <unknown>
#12 0x559d7fd1b850 <unknown>
#13 0x559d7fd2adec <unknown>
#14 0x7ff0c9d98ac3 <unknown>

Finding web-page failed:  Alert Text: 잘못된 접근 경로입니다. 다시 시도해 주세요.
Message: unexpected alert open: {Alert text : 잘못된 접근 경로입니다. 다시 시도해 주세요.}
  (Session info: chrome-headless-shell=126.0.6478.126)
Stacktrace:
#0 0x5619f4b9dcba <unknown>
#1 0x5619f4880e2c <unknown>
#2 0x5619f490fd63 <unknown>
#3 0x5619f48f0363 <unknown>
#4 0x5619f48c0247 <unknown>
#5 0x5619f48c0b9e <unknown>
#6 0x5619f4b6428b <unknown>
#7 0x5619f4b68331 <unknown>
#8 0x5619f4b4fb3e <unknown>
#9 0x5619f4b68e92 <unknown>
#10 0x5619f4b347df <unknown>
#11 0x5619f4b8d678 <unknown>
#12 0x5619f4b8d850 <unknown>
#13 0x5619f4b9cdec <unknown>
#14 0x7f2234e3dac3 <unknown>

response completed2
Internal Server Error: /news_study/
Traceback (most recent call last):
  File "/root/pyDjangoDEV/mdmproj1/.venw/lib/python3.8/site-packages/django/core/handlers/exception.py", line 55, in inner
    response = get_response(request)
  File "/root/pyDjangoDEV/mdmproj1/.venw/lib/python3.8/site-packages/django/core/handlers/base.py", line 197, in _get_response
    response = wrapped_callback(request, *callback_args, **callback_kwargs)
  File "/root/pyDjangoDEV/mdmproj1/app_news_study/views.py", line 32, in news_study
    html, soup = proj_comn_func.url_parsing_with_webdriver(url, "1")
  File "/root/pyDjangoDEV/mdmproj1/proj_common/common.py", line 45, in url_parsing_with_webdriver
    driver = webdriver.Chrome(service=service, options=options)
  File "/root/pyDjangoDEV/mdmproj1/.venw/lib/python3.8/site-packages/selenium/webdriver/chrome/webdriver.py", line 45, in __init__
    super().__init__(
  File "/root/pyDjangoDEV/mdmproj1/.venw/lib/python3.8/site-packages/selenium/webdriver/chromium/webdriver.py", line 61, in __init__
    super().__init__(command_executor=executor, options=options)
  File "/root/pyDjangoDEV/mdmproj1/.venw/lib/python3.8/site-packages/selenium/webdriver/remote/webdriver.py", line 209, in __init__
    self.start_session(capabilities)
  File "/root/pyDjangoDEV/mdmproj1/.venw/lib/python3.8/site-packages/selenium/webdriver/remote/webdriver.py", line 293, in start_session
    response = self.execute(Command.NEW_SESSION, caps)["value"]
  File "/root/pyDjangoDEV/mdmproj1/.venw/lib/python3.8/site-packages/selenium/webdriver/remote/webdriver.py", line 348, in execute
    self.error_handler.check_response(response)
  File "/root/pyDjangoDEV/mdmproj1/.venw/lib/python3.8/site-packages/selenium/webdriver/remote/errorhandler.py", line 229, in check_response
    raise exception_class(message, screen, stacktrace)
selenium.common.exceptions.SessionNotCreatedException: Message: session not created
from disconnected: unable to connect to renderer
Stacktrace:
#0 0x560581093cba <unknown>
#1 0x560580d76e2c <unknown>
#2 0x560580db21c1 <unknown>
#3 0x560580dac742 <unknown>
#4 0x560580da817b <unknown>
#5 0x560580df2c49 <unknown>
#6 0x560580de6363 <unknown>
#7 0x560580db6247 <unknown>
#8 0x560580db6b9e <unknown>
#9 0x56058105a28b <unknown>
#10 0x56058105e331 <unknown>
#11 0x560581045b3e <unknown>
#12 0x56058105ee92 <unknown>
#13 0x56058102a7df <unknown>
#14 0x560581083678 <unknown>
#15 0x560581083850 <unknown>
#16 0x560581092dec <unknown>
#17 0x7fc4da438ac3 <unknown>

Internal Server Error: /news_study/
Traceback (most recent call last):
  File "/root/pyDjangoDEV/mdmproj1/.venw/lib/python3.8/site-packages/django/core/handlers/exception.py", line 55, in inner
    response = get_response(request)
  File "/root/pyDjangoDEV/mdmproj1/.venw/lib/python3.8/site-packages/django/core/handlers/base.py", line 197, in _get_response
    response = wrapped_callback(request, *callback_args, **callback_kwargs)
  File "/root/pyDjangoDEV/mdmproj1/app_news_study/views.py", line 57, in news_study
    list_keyitems = app_comn_func.get_url_keyitems(link)
  File "/root/pyDjangoDEV/mdmproj1/app_news_study/app_mdl_common/common.py", line 62, in get_url_keyitems
    html, soup = proj_comn_func.url_parsing_with_webdriver(url, "3")
  File "/root/pyDjangoDEV/mdmproj1/proj_common/common.py", line 45, in url_parsing_with_webdriver
    driver = webdriver.Chrome(service=service, options=options)
  File "/root/pyDjangoDEV/mdmproj1/.venw/lib/python3.8/site-packages/selenium/webdriver/chrome/webdriver.py", line 45, in __init__
    super().__init__(
  File "/root/pyDjangoDEV/mdmproj1/.venw/lib/python3.8/site-packages/selenium/webdriver/chromium/webdriver.py", line 61, in __init__
    super().__init__(command_executor=executor, options=options)
  File "/root/pyDjangoDEV/mdmproj1/.venw/lib/python3.8/site-packages/selenium/webdriver/remote/webdriver.py", line 209, in __init__
    self.start_session(capabilities)
  File "/root/pyDjangoDEV/mdmproj1/.venw/lib/python3.8/site-packages/selenium/webdriver/remote/webdriver.py", line 293, in start_session
    response = self.execute(Command.NEW_SESSION, caps)["value"]
  File "/root/pyDjangoDEV/mdmproj1/.venw/lib/python3.8/site-packages/selenium/webdriver/remote/webdriver.py", line 348, in execute
    self.error_handler.check_response(response)
  File "/root/pyDjangoDEV/mdmproj1/.venw/lib/python3.8/site-packages/selenium/webdriver/remote/errorhandler.py", line 229, in check_response
    raise exception_class(message, screen, stacktrace)
selenium.common.exceptions.SessionNotCreatedException: Message: session not created
from disconnected: unable to connect to renderer
Stacktrace:
#0 0x561d82f6acba <unknown>
#1 0x561d82c4de2c <unknown>
#2 0x561d82c891c1 <unknown>
#3 0x561d82c83742 <unknown>
#4 0x561d82c7f17b <unknown>
#5 0x561d82cc9c49 <unknown>
#6 0x561d82cbd363 <unknown>
#7 0x561d82c8d247 <unknown>
#8 0x561d82c8db9e <unknown>
#9 0x561d82f3128b <unknown>
#10 0x561d82f35331 <unknown>
#11 0x561d82f1cb3e <unknown>
#12 0x561d82f35e92 <unknown>
#13 0x561d82f017df <unknown>
#14 0x561d82f5a678 <unknown>
#15 0x561d82f5a850 <unknown>
#16 0x561d82f69dec <unknown>
#17 0x7f4cb95e7ac3 <unknown>

Internal Server Error: /news_study/
Traceback (most recent call last):
  File "/root/pyDjangoDEV/mdmproj1/.venw/lib/python3.8/site-packages/django/core/handlers/exception.py", line 55, in inner
    response = get_response(request)
  File "/root/pyDjangoDEV/mdmproj1/.venw/lib/python3.8/site-packages/django/core/handlers/base.py", line 197, in _get_response
    response = wrapped_callback(request, *callback_args, **callback_kwargs)
  File "/root/pyDjangoDEV/mdmproj1/app_news_study/views.py", line 57, in news_study
    list_keyitems = app_comn_func.get_url_keyitems(link)
  File "/root/pyDjangoDEV/mdmproj1/app_news_study/app_mdl_common/common.py", line 62, in get_url_keyitems
    html, soup = proj_comn_func.url_parsing_with_webdriver(url, "3")
  File "/root/pyDjangoDEV/mdmproj1/proj_common/common.py", line 45, in url_parsing_with_webdriver
    driver = webdriver.Chrome(service=service, options=options)
  File "/root/pyDjangoDEV/mdmproj1/.venw/lib/python3.8/site-packages/selenium/webdriver/chrome/webdriver.py", line 45, in __init__
    super().__init__(
  File "/root/pyDjangoDEV/mdmproj1/.venw/lib/python3.8/site-packages/selenium/webdriver/chromium/webdriver.py", line 61, in __init__
    super().__init__(command_executor=executor, options=options)
  File "/root/pyDjangoDEV/mdmproj1/.venw/lib/python3.8/site-packages/selenium/webdriver/remote/webdriver.py", line 209, in __init__
    self.start_session(capabilities)
  File "/root/pyDjangoDEV/mdmproj1/.venw/lib/python3.8/site-packages/selenium/webdriver/remote/webdriver.py", line 293, in start_session
    response = self.execute(Command.NEW_SESSION, caps)["value"]
  File "/root/pyDjangoDEV/mdmproj1/.venw/lib/python3.8/site-packages/selenium/webdriver/remote/webdriver.py", line 348, in execute
    self.error_handler.check_response(response)
  File "/root/pyDjangoDEV/mdmproj1/.venw/lib/python3.8/site-packages/selenium/webdriver/remote/errorhandler.py", line 229, in check_response
    raise exception_class(message, screen, stacktrace)
selenium.common.exceptions.SessionNotCreatedException: Message: session not created
from disconnected: unable to connect to renderer
Stacktrace:
#0 0x559fe8673cba <unknown>
#1 0x559fe8356e2c <unknown>
#2 0x559fe83921c1 <unknown>
#3 0x559fe838c742 <unknown>
#4 0x559fe838817b <unknown>
#5 0x559fe83d2c49 <unknown>
#6 0x559fe83c6363 <unknown>
#7 0x559fe8396247 <unknown>
#8 0x559fe8396b9e <unknown>
#9 0x559fe863a28b <unknown>
#10 0x559fe863e331 <unknown>
#11 0x559fe8625b3e <unknown>
#12 0x559fe863ee92 <unknown>
#13 0x559fe860a7df <unknown>
#14 0x559fe8663678 <unknown>
#15 0x559fe8663850 <unknown>
#16 0x559fe8672dec <unknown>
#17 0x7fe9cb3f0ac3 <unknown>

response completed2
